Workbook

Sheet Sheet1
A3: Sum of Revenue (₹) | B3: Column Labels
A4: Row Labels | B4: Appliances | C4: Electronics | D4: Fitness | E4: Footwear | F4: Furniture | G4: Nutrition | H4: Grand Total
A5: Central | B5: 153800 | C5: 653500 | D5: 27400 | E5: 118500 | F5: 123500 | G5: 65700 | H5: 1142400
A6: East | B6: 206000 | C6: 627900 | D6: 19300 | E6: 110700 | F6: 165100 | G6: 60700 | H6: 1189700
A7: North | B7: 232200 | C7: 613000 | D7: 29900 | E7: 60600 | F7: 200100 | G7: 37200 | H7: 1173000
A8: South | B8: 187200 | C8: 554100 | D8: 31700 | E8: 38300 | F8: 248200 | G8: 37600 | H8: 1097100
A9: West | B9: 155100 | C9: 557100 | D9: 24400 | E9: 82500 | F9: 200700 | G9: 49300 | H9: 1069100
A10: Grand Total | B10: 934300 | C10: 3005600 | D10: 132700 | E10: 410600 | F10: 937600 | G10: 250500 | H10: 5671300

Sheet Raw Data
B1: DAY 16 — WEEK 4 MINI-PROJECT | Raw Data (DO NOT MODIFY)
B2: 150 transactions · Jan 2024 – Jun 2025 · 5 Regions · 6 Categories · Source for ALL formulas and pivots
B3: Order ID | C3: Order Date | D3: Region | E3: Category | F3: Product | G3: Revenue (₹) | H3: Cost (₹) | I3: Units | J3: Margin % | K3: Sales Rep
B4: ORD-001 | C4: 45292 | D4: North | E4: Electronics | F4: Smart TV 55" | G4: 49900 | H4: 32600 | I4: 2 | J4: 0.346 | K4: Arjun Sharma
B5: ORD-002 | C5: 45297 | D5: South | E5: Appliances | F5: Microwave | G5: 26500 | H5: 14800 | I5: 3 | J5: 0.442 | K5: Sneha Iyer
B6: ORD-003 | C6: 45298 | D6: East | E6: Footwear | F6: Formal Leather | G6: 8500 | H6: 6100 | I6: 2 | J6: 0.288 | K6: Karan Singh
B7: ORD-004 | C7: 45303 | D7: West | E7: Fitness | F7: Yoga Mat | G7: 4600 | H7: 2600 | I7: 4 | J7: 0.424 | K7: Meera Joshi
B8: ORD-005 | C8: 45305 | D8: Central | E8: Nutrition | F8: Protein Powder | G8: 9100 | H8: 5000 | I8: 4 | J8: 0.448 | K8: Siddharth Rao
B9: ORD-006 | C9: 45307 | D9: North | E9: Furniture | F9: Office Chair | G9: 43600 | H9: 28500 | I9: 4 | J9: 0.347 | K9: Priya Nair
B10: ORD-007 | C10: 45310 | D10: South | E10: Electronics | F10: Smart TV 55" | G10: 83600 | H10: 53300 | I10: 3 | J10: 0.362 | K10: Rohit Verma
B11: ORD-008 | C11: 45313 | D11: East | E11: Appliances | F11: Microwave | G11: 36500 | H11: 23300 | I11: 4 | J11: 0.361 | K11: Anjali Das
B12: ORD-009 | C12: 45318 | D12: West | E12: Footwear | F12: Formal Leather | G12: 27500 | H12: 14200 | I12: 7 | J12: 0.483 | K12: Vikram Patel
B13: ORD-010 | C13: 45321 | D13: Central | E13: Fitness | F13: Yoga Mat | G13: 6300 | H13: 3400 | I13: 5 | J13: 0.455 | K13: Deepika Menon
B14: ORD-011 | C14: 45324 | D14: North | E14: Nutrition | F14: Protein Powder | G14: 4700 | H14: 3000 | I14: 2 | J14: 0.371 | K14: Arjun Sharma
B15: ORD-012 | C15: 45326 | D15: South | E15: Furniture | F15: Office Chair | G15: 57900 | H15: 33100 | I15: 5 | J15: 0.428 | K15: Sneha Iyer
... B153: ORD-150 | C153: 45741 | D153: Central | E153: Furniture | F153: Office Chair | G153: 57300 | H153: 39000 | I153: 5 | J153: 0.32 | K153: Deepika Menon

Sheet Dashboard (Your Work)
B1: REGIONAL SALES PERFORMANCE DASHBOARD | Jan 2024 – Jun 2025
B2: Source: Raw Data sheet · All formulas must reference 'Raw Data'!B4:K153 · Do not hardcode values
B3: SECTION 1 — KEY PERFORMANCE INDICATORS (Use SUMIF / COUNT / AVERAGE from Raw Data)
B4: Total Revenue (₹) | D4: Total Orders | F4: Avg Order Value (₹) | H4: Total Units Sold | J4: Avg Margin %
B5: =SUMIF('Raw Data'!B4:B153,"*",'Raw Data'!G4:G153) -> 5671300 | D5: =COUNTA('Raw Data'!B4:B153) -> 150 | F5: =AVERAGEIF('Raw Data'!B4:B153,"*",'Raw Data'!G4:G153) -> 37808.667 | H5: =SUM('Raw Data'!I4:I153) -> 629 | J5: =AVERAGE('Raw Data'!J4:J153) -> 0.40434667
B8: SECTION 2 — REVENUE SUMMARY BY REGION (SUMIF per region)
B9: Region | C9: Total Revenue (₹) | D9: % of Total | E9: Total Orders | F9: Avg Order Value (₹) | G9: Avg Margin % | H9: Performance Tag
B10: East | C10: =SUMIF('Raw Data'!D4:D153,"East",'Raw Data'!G4:G153) -> 1189700 | D10: =C10/SUM($C$10:$C$14) -> 0.20977554 | E10: =COUNTIF('Raw Data'!D4:D153,"East") -> 30 | F10: =AVERAGEIF('Raw Data'!D4:D153,"East",'Raw Data'!G4:G153) -> 39656.667 | G10: =AVERAGEIF('Raw Data'!D4:D153,"East",'Raw Data'!J4:J153) -> 0.39613333 | H10: =IF(C10=MAX($C$10:$C$14),"Top Region",IF(C10>=AVERAGE($C$10:$C$14),"Above Avg","Below Avg")) -> Top Region
B11: North | C11: =SUMIF('Raw Data'!D4:D153,"North",'Raw Data'!G4:G153) -> 1173000 | D11: =C11/SUM($C$10:$C$14) -> 0.20683089 | E11: =COUNTIF('Raw Data'!D4:D153,"North") -> 30 | F11: =AVERAGEIF('Raw Data'!D4:D153,"North",'Raw Data'!G4:G153) -> 39100 | G11: =AVERAGEIF('Raw Data'!D4:D153,"North",'Raw Data'!J4:J153) -> 0.394 | H11: =IF(C11=MAX($C$10:$C$14),"Top Region",IF(C11>=AVERAGE($C$10:$C$14),"Above Avg","Below Avg")) -> Above Avg
B12: Central | C12: =SUMIF('Raw Data'!D4:D153,"Central",'Raw Data'!G4:G153) -> 1142400 | D12: =C12/SUM($C$10:$C$14) -> 0.2014353 | E12: =COUNTIF('Raw Data'!D4:D153,"Central") -> 30 | F12: =AVERAGEIF('Raw Data'!D4:D153,"Central",'Raw Data'!G4:G153) -> 38080 | G12: =AVERAGEIF('Raw Data'!D4:D153,"Central",'Raw Data'!J4:J153) -> 0.40253333 | H12: =IF(C12=MAX($C$10:$C$14),"Top Region",IF(C12>=AVERAGE($C$10:$C$14),"Above Avg","Below Avg")) -> Above Avg
B13: South | C13: =SUMIF('Raw Data'!D4:D153,"South",'Raw Data'!G4:G153) -> 1097100 | D13: =C13/SUM($C$10:$C$14) -> 0.19344771 | E13: =COUNTIF('Raw Data'!D4:D153,"South") -> 30 | F13: =AVERAGEIF('Raw Data'!D4:D153,"South",'Raw Data'!G4:G153) -> 36570 | G13: =AVERAGEIF('Raw Data'!D4:D153,"South",'Raw Data'!J4:J153) -> 0.4214 | H13: =IF(C13=MAX($C$10:$C$14),"Top Region",IF(C13>=AVERAGE($C$10:$C$14),"Above Avg","Below Avg")) -> Below Avg
B14: West | C14: =SUMIF('Raw Data'!D4:D153,"West",'Raw Data'!G4:G153) -> 1069100 | D14: =C14/SUM($C$10:$C$14) -> 0.18851057 | E14: =COUNTIF('Raw Data'!D4:D153,"West") -> 30 | F14: =AVERAGEIF('Raw Data'!D4:D153,"West",'Raw Data'!G4:G153) -> 35636.667 | G14: =AVERAGEIF('Raw Data'!D4:D153,"West",'Raw Data'!J4:J153) -> 0.40766667 | H14: =IF(C14=MAX($C$10:$C$14),"Top Region",IF(C14>=AVERAGE($C$10:$C$14),"Above Avg","Below Avg")) -> Below Avg
B15: GRAND TOTAL | C15: =SUM(C10:C14) -> 5671300 | D15: =SUM(D10:D14) -> 1 | E15: =SUM(E10:E14) -> 150 | F15: =AVERAGE(F10:F14) -> 37808.667 | G15: =AVERAGE(G10:G14) -> 0.40434667 | H15: —
B17: SECTION 3 — REVENUE SUMMARY BY CATEGORY (SUMIF per category + Conditional Formatting)
B18: Category | C18: Total Revenue (₹) | D18: % of Total | E18: Total Orders | F18: Avg Margin % | G18: Revenue Bar
B19: Electronics | C19: =SUMIF('Raw Data'!E4:E153,"Electronics",'Raw Data'!G4:G153) -> 3005600 | D19: =C19/SUM($C$19:$C$24) -> 0.52996667 | E19: =COUNTIF('Raw Data'!E4:E153,"Electronics") -> 25 | F19: =AVERAGEIF('Raw Data'!E4:E153,"Electronics",'Raw Data'!J4:J153) -> 0.424 | G19: =C19 -> 3005600
B20: Furniture | C20: =SUMIF('Raw Data'!E4:E153,"Furniture",'Raw Data'!G4:G153) -> 937600 | D20: =C20/SUM($C$19:$C$24) -> 0.16532365 | E20: =COUNTIF('Raw Data'!E4:E153,"Furniture") -> 25 | F20: =AVERAGEIF('Raw Data'!E4:E153,"Furniture",'Raw Data'!J4:J153) -> 0.3942 | G20: =C20 -> 937600
B21: Appliances | C21: =SUMIF('Raw Data'!E4:E153,"Appliances",'Raw Data'!G4:G153) -> 934300 | D21: =C21/SUM($C$19:$C$24) -> 0.16474177 | E21: =COUNTIF('Raw Data'!E4:E153,"Appliances") -> 25 | F21: =AVERAGEIF('Raw Data'!E4:E153,"Appliances",'Raw Data'!J4:J153) -> 0.40096 | G21: =C21 -> 934300
B22: Footwear | C22: =SUMIF('Raw Data'!E4:E153,"Footwear",'Raw Data'!G4:G153) -> 410600 | D22: =C22/SUM($C$19:$C$24) -> 0.072399626 | E22: =COUNTIF('Raw Data'!E4:E153,"Footwear") -> 25 | F22: =AVERAGEIF('Raw Data'!E4:E153,"Footwear",'Raw Data'!J4:J153) -> 0.39904 | G22: =C22 -> 410600
B23: Nutrition | C23: =SUMIF('Raw Data'!E4:E153,"Nutrition",'Raw Data'!G4:G153) -> 250500 | D23: =C23/SUM($C$19:$C$24) -> 0.044169767 | E23: =COUNTIF('Raw Data'!E4:E153,"Nutrition") -> 25 | F23: =AVERAGEIF('Raw Data'!E4:E153,"Nutrition",'Raw Data'!J4:J153) -> 0.41424 | G23: =C23 -> 250500
B24: Fitness | C24: =SUMIF('Raw Data'!E4:E153,"Fitness",'Raw Data'!G4:G153) -> 132700 | D24: =C24/SUM($C$19:$C$24) -> 0.023398515 | E24: =COUNTIF('Raw Data'!E4:E153,"Fitness") -> 25 | F24: =AVERAGEIF('Raw Data'!E4:E153,"Fitness",'Raw Data'!J4:J153) -> 0.39364 | G24: =C24 -> 132700
B25: GRAND TOTAL | C25: =SUM(C19:C24) -> 5671300 | D25: =SUM(D19:D24) -> 1 | E25: =SUM(E19:E24) -> 150 | F25: =AVERAGE(F19:F24) -> 0.40434667 | G25: —
B27: SECTION 4 — SALES REP LEADERBOARD (SUMIF / COUNTIF / IFS — rank your team)
B28: Sales Rep | C28: Region | D28: Revenue (₹) | E28: Orders | F28: Avg Order Value (₹) | G28: Performance Grade
B29: Siddharth Rao | C29: Central | D29: =SUMIF('Raw Data'!K4:K153,"Siddharth Rao",'Raw Data'!G4:G153) -> 837700 | E29: =COUNTIF('Raw Data'!K4:K153,"Siddharth Rao") -> 15 | F29: =IFERROR(D29/E29,0) -> 55846.667 | G29: =IF(D29>=LARGE($D$29:$D$38,3),"High Performer",IF(D29>=AVERAGE($D$29:$D$38),"On Target","Needs Coaching")) -> High Performer
B30: Karan Singh | C30: East | D30: =SUMIF('Raw Data'!K4:K153,"Karan Singh",'Raw Data'!G4:G153) -> 799300 | E30: =COUNTIF('Raw Data'!K4:K153,"Karan Singh") -> 15 | F30: =IFERROR(D30/E30,0) -> 53286.667 | G30: =IF(D30>=LARGE($D$29:$D$38,3),"High Performer",IF(D30>=AVERAGE($D$29:$D$38),"On Target","Needs Coaching")) -> High Performer
B31: Arjun Sharma | C31: North | D31: =SUMIF('Raw Data'!K4:K153,"Arjun Sharma",'Raw Data'!G4:G153) -> 710800 | E31: =COUNTIF('Raw Data'!K4:K153,"Arjun Sharma") -> 15 | F31: =IFERROR(D31/E31,0) -> 47386.667 | G31: =IF(D31>=LARGE($D$29:$D$38,3),"High Performer",IF(D31>=AVERAGE($D$29:$D$38),"On Target","Needs Coaching")) -> High Performer
B32: Vikram Patel | C32: West | D32: =SUMIF('Raw Data'!K4:K153,"Vikram Patel",'Raw Data'!G4:G153) -> 688900 | E32: =COUNTIF('Raw Data'!K4:K153,"Vikram Patel") -> 15 | F32: =IFERROR(D32/E32,0) -> 45926.667 | G32: =IF(D32>=LARGE($D$29:$D$38,3),"High Performer",IF(D32>=AVERAGE($D$29:$D$38),"On Target","Needs Coaching")) -> On Target
B33: Rohit Verma | C33: South | D33: =SUMIF('Raw Data'!K4:K153,"Rohit Verma",'Raw Data'!G4:G153) -> 630000 | E33: =COUNTIF('Raw Data'!K4:K153,"Rohit Verma") -> 15 | F33: =IFERROR(D33/E33,0) -> 42000 | G33: =IF(D33>=LARGE($D$29:$D$38,3),"High Performer",IF(D33>=AVERAGE($D$29:$D$38),"On Target","Needs Coaching")) -> On Target
B34: Sneha Iyer | C34: South | D34: =SUMIF('Raw Data'!K4:K153,"Sneha Iyer",'Raw Data'!G4:G153) -> 467100 | E34: =COUNTIF('Raw Data'!K4:K153,"Sneha Iyer") -> 15 | F34: =IFERROR(D34/E34,0) -> 31140 | G34: =IF(D34>=LARGE($D$29:$D$38,3),"High Performer",IF(D34>=AVERAGE($D$29:$D$38),"On Target","Needs Coaching")) -> Needs Coaching
B35: Priya Nair | C35: North | D35: =SUMIF('Raw Data'!K4:K153,"Priya Nair",'Raw Data'!G4:G153) -> 462200 | E35: =COUNTIF('Raw Data'!K4:K153,"Priya Nair") -> 15 | F35: =IFERROR(D35/E35,0) -> 30813.333 | G35: =IF(D35>=LARGE($D$29:$D$38,3),"High Performer",IF(D35>=AVERAGE($D$29:$D$38),"On Target","Needs Coaching")) -> Needs Coaching
B36: Anjali Das | C36: East | D36: =SUMIF('Raw Data'!K4:K153,"Anjali Das",'Raw Data'!G4:G153) -> 390400 | E36: =COUNTIF('Raw Data'!K4:K153,"Anjali Das") -> 15 | F36: =IFERROR(D36/E36,0) -> 26026.667 | G36: =IF(D36>=LARGE($D$29:$D$38,3),"High Performer",IF(D36>=AVERAGE($D$29:$D$38),"On Target","Needs Coaching")) -> Needs Coaching
B37: Meera Joshi | C37: West | D37: =SUMIF('Raw Data'!K4:K153,"Meera Joshi",'Raw Data'!G4:G153) -> 380200 | E37: =COUNTIF('Raw Data'!K4:K153,"Meera Joshi") -> 15 | F37: =IFERROR(D37/E37,0) -> 25346.667 | G37: =IF(D37>=LARGE($D$29:$D$38,3),"High Performer",IF(D37>=AVERAGE($D$29:$D$38),"On Target","Needs Coaching")) -> Needs Coaching
B38: Deepika Menon | C38: Central | D38: =SUMIF('Raw Data'!K4:K153,"Deepika Menon",'Raw Data'!G4:G153) -> 304700 | E38: =COUNTIF('Raw Data'!K4:K153,"Deepika Menon") -> 15 | F38: =IFERROR(D38/E38,0) -> 20313.333 | G38: =IF(D38>=LARGE($D$29:$D$38,3),"High Performer",IF(D38>=AVERAGE($D$29:$D$38),"On Target","Needs Coaching")) -> Needs Coaching
B40: SECTION 5 — CHART ZONE (Insert 2 charts below: Revenue by Region bar + Revenue Trend line)
B41: 📊 CHART 1 — Revenue by Region (Clustered Bar) Source: Section 2 → C10:C14 vs B10:B14 Insert → Chart → Clustered Bar Title: 'Revenue by Region' Add data labels. No 3D. No gridlines. | G41: 📈 CHART 2 — Revenue Trend by Month (Line) Source: Build a monthly summary table first (use SUMIFS with month) Insert → Chart → Line Title: 'Monthly Revenue Trend' Add markers. Show trend direction.
B66: SECTION 6 — EXECUTIVE SUMMARY (Write 5 business insights: Number + Reason + Action format)
B67: Insight 1
B68: Q1. Which region generates the highest revenue, and by what % does it lead the second-highest? → Number: [revenue figure + % lead] | Reason: [why it matters] | Action: [what the business should do] | E68: The East region generates the highest-revenue at Rs 1189700, leading the second highest region(North) by 1.42%.This narrow lead indicates a highly competitive landscape where East has a slight edge in customer volume. Perform a success audit in the East to identify specifit sales tactics that can be exported to lower performing West region to boost its numbers.
B70: Insight 2
...

Sheet Monthly Summary
B1: DAY 16 — MONTHLY SUMMARY TABLE | Build your trend chart from this sheet
B2: These SUMIFS formulas pull from Raw Data. Source for your Trend Line chart.
B3: Month | C3: Period | D3: Total Revenue (₹) | E3: Total Orders | F3: Avg Margin % | G3: MoM Change (₹) | H3: Trend Tag
B4: 1 | C4: Jan-24 | D4: =SUMPRODUCT(('Raw Data'!G4:G153)*(MONTH('Raw Data'!C4:C153)=1)*(YEAR('Raw Data'!C4:C153)=2024)) -> 296100 | E4: =SUMPRODUCT(('Raw Data'!B4:B153<>"")*(MONTH('Raw Data'!C4:C153)=1)*(YEAR('Raw Data'!C4:C153)=2024)) -> 10 | F4: =IFERROR(SUMPRODUCT(('Raw Data'!J4:J153)*(MONTH('Raw Data'!C4:C153)=1)*(YEAR('Raw Data'!C4:C153)=2024))/E4,0) -> 0.3956 | G4: — | H4: —
B5: 2 | C5: Feb-24 | D5: =SUMPRODUCT(('Raw Data'!G4:G153)*(MONTH('Raw Data'!C4:C153)=2)*(YEAR('Raw Data'!C4:C153)=2024)) -> 444900 | E5: =SUMPRODUCT(('Raw Data'!B4:B153<>"")*(MONTH('Raw Data'!C4:C153)=2)*(YEAR('Raw Data'!C4:C153)=2024)) -> 10 | F5: =IFERROR(SUMPRODUCT(('Raw Data'!J4:J153)*(MONTH('Raw Data'!C4:C153)=2)*(YEAR('Raw Data'!C4:C153)=2024))/E5,0) -> 0.3985 | G5: =D5-D4 -> 148800 | H5: =IF(G5>0,"▲ Growth","▼ Decline") -> ▲ Growth
B6: 3 | C6: Mar-24 | D6: =SUMPRODUCT(('Raw Data'!G4:G153)*(MONTH('Raw Data'!C4:C153)=3)*(YEAR('Raw Data'!C4:C153)=2024)) -> 398200 | E6: =SUMPRODUCT(('Raw Data'!B4:B153<>"")*(MONTH('Raw Data'!C4:C153)=3)*(YEAR('Raw Data'!C4:C153)=2024)) -> 10 | F6: =IFERROR(SUMPRODUCT(('Raw Data'!J4:J153)*(MONTH('Raw Data'!C4:C153)=3)*(YEAR('Raw Data'!C4:C153)=2024))/E6,0) -> 0.4195 | G6: =D6-D5 -> -46700 | H6: =IF(G6>0,"▲ Growth","▼ Decline") -> ▼ Decline
B7: 4 | C7: Apr-24 | D7: =SUMPRODUCT(('Raw Data'!G4:G153)*(MONTH('Raw Data'!C4:C153)=4)*(YEAR('Raw Data'!C4:C153)=2024)) -> 413100 | E7: =SUMPRODUCT(('Raw Data'!B4:B153<>"")*(MONTH('Raw Data'!C4:C153)=4)*(YEAR('Raw Data'!C4:C153)=2024)) -> 10 | F7: =IFERROR(SUMPRODUCT(('Raw Data'!J4:J153)*(MONTH('Raw Data'!C4:C153)=4)*(YEAR('Raw Data'!C4:C153)=2024))/E7,0) -> 0.4139 | G7: =D7-D6 -> 14900 | H7: =IF(G7>0,"▲ Growth","▼ Decline") -> ▲ Growth
B8: 5 | C8: May-24 | D8: =SUMPRODUCT(('Raw Data'!G4:G153)*(MONTH('Raw Data'!C4:C153)=5)*(YEAR('Raw Data'!C4:C153)=2024)) -> 450300 | E8: =SUMPRODUCT(('Raw Data'!B4:B153<>"")*(MONTH('Raw Data'!C4:C153)=5)*(YEAR('Raw Data'!C4:C153)=2024)) -> 11 | F8: =IFERROR(SUMPRODUCT(('Raw Data'!J4:J153)*(MONTH('Raw Data'!C4:C153)=5)*(YEAR('Raw Data'!C4:C153)=2024))/E8,0) -> 0.40936364 | G8: =D8-D7 -> 37200 | H8: =IF(G8>0,"▲ Growth","▼ Decline") -> ▲ Growth
B9: 6 | C9: Jun-24 | D9: =SUMPRODUCT(('Raw Data'!G4:G153)*(MONTH('Raw Data'!C4:C153)=6)*(YEAR('Raw Data'!C4:C153)=2024)) -> 481900 | E9: =SUMPRODUCT(('Raw Data'!B4:B153<>"")*(MONTH('Raw Data'!C4:C153)=6)*(YEAR('Raw Data'!C4:C153)=2024)) -> 10 | F9: =IFERROR(SUMPRODUCT(('Raw Data'!J4:J153)*(MONTH('Raw Data'!C4:C153)=6)*(YEAR('Raw Data'!C4:C153)=2024))/E9,0) -> 0.4201 | G9: =D9-D8 -> 31600 | H9: =IF(G9>0,"▲ Growth","▼ Decline") -> ▲ Growth
B10: 7 | C10: Jul-24 | D10: =SUMPRODUCT(('Raw Data'!G4:G153)*(MONTH('Raw Data'!C4:C153)=7)*(YEAR('Raw Data'!C4:C153)=2024)) -> 259000 | E10: =SUMPRODUCT(('Raw Data'!B4:B153<>"")*(MONTH('Raw Data'!C4:C153)=7)*(YEAR('Raw Data'!C4:C153)=2024)) -> 10 | F10: =IFERROR(SUMPRODUCT(('Raw Data'!J4:J153)*(MONTH('Raw Data'!C4:C153)=7)*(YEAR('Raw Data'!C4:C153)=2024))/E10,0) -> 0.3905 | G10: =D10-D9 -> -222900 | H10: =IF(G10>0,"▲ Growth","▼ Decline") -> ▼ Decline
B11: 8 | C11: Aug-24 | D11: =SUMPRODUCT(('Raw Data'!G4:G153)*(MONTH('Raw Data'!C4:C153)=8)*(YEAR('Raw Data'!C4:C153)=2024)) -> 252300 | E11: =SUMPRODUCT(('Raw Data'!B4:B153<>"")*(MONTH('Raw Data'!C4:C153)=8)*(YEAR('Raw Data'!C4:C153)=2024)) -> 11 | F11: =IFERROR(SUMPRODUCT(('Raw Data'!J4:J153)*(MONTH('Raw Data'!C4:C153)=8)*(YEAR('Raw Data'!C4:C153)=2024))/E11,0) -> 0.42027273 | G11: =D11-D10 -> -6700 | H11: =IF(G11>0,"▲ Growth","▼ Decline") -> ▼ Decline
B12: 9 | C12: Sep-24 | D12: =SUMPRODUCT(('Raw Data'!G4:G153)*(MONTH('Raw Data'!C4:C153)=9)*(YEAR('Raw Data'!C4:C153)=2024)) -> 233900 | E12: =SUMPRODUCT(('Raw Data'!B4:B153<>"")*(MONTH('Raw Data'!C4:C153)=9)*(YEAR('Raw Data'!C4:C153)=2024)) -> 9 | F12: =IFERROR(SUMPRODUCT(('Raw Data'!J4:J153)*(MONTH('Raw Data'!C4:C153)=9)*(YEAR('Raw Data'!C4:C153)=2024))/E12,0) -> 0.39555556 | G12: =D12-D11 -> -18400 | H12: =IF(G12>0,"▲ Growth","▼ Decline") -> ▼ Decline
B13: 10 | C13: Oct-24 | D13: =SUMPRODUCT(('Raw Data'!G4:G153)*(MONTH('Raw Data'!C4:C153)=10)*(YEAR('Raw Data'!C4:C153)=2024)) -> 335400 | E13: =SUMPRODUCT(('Raw Data'!B4:B153<>"")*(MONTH('Raw Data'!C4:C153)=10)*(YEAR('Raw Data'!C4:C153)=2024)) -> 11 | F13: =IFERROR(SUMPRODUCT(('Raw Data'!J4:J153)*(MONTH('Raw Data'!C4:C153)=10)*(YEAR('Raw Data'!C4:C153)=2024))/E13,0) -> 0.39163636 | G13: =D13-D12 -> 101500 | H13: =IF(G13>0,"▲ Growth","▼ Decline") -> ▲ Growth
B14: 11 | C14: Nov-24 | D14: =SUMPRODUCT(('Raw Data'!G4:G153)*(MONTH('Raw Data'!C4:C153)=11)*(YEAR('Raw Data'!C4:C153)=2024)) -> 570300 | E14: =SUMPRODUCT(('Raw Data'!B4:B153<>"")*(MONTH('Raw Data'!C4:C153)=11)*(YEAR('Raw Data'!C4:C153)=2024)) -> 10 | F14: =IFERROR(SUMPRODUCT(('Raw Data'!J4:J153)*(MONTH('Raw Data'!C4:C153)=11)*(YEAR('Raw Data'!C4:C153)=2024))/E14,0) -> 0.3881 | G14: =D14-D13 -> 234900 | H14: =IF(G14>0,"▲ Growth","▼ Decline") -> ▲ Growth
B15: 12 | C15: Dec-24 | D15: =SUMPRODUCT(('Raw Data'!G4:G153)*(MONTH('Raw Data'!C4:C153)=12)*(YEAR('Raw Data'!C4:C153)=2024)) -> 528500 | E15: =SUMPRODUCT(('Raw Data'!B4:B153<>"")*(MONTH('Raw Data'!C4:C153)=12)*(YEAR('Raw Data'!C4:C153)=2024)) -> 10 | F15: =IFERROR(SUMPRODUCT(('Raw Data'!J4:J153)*(MONTH('Raw Data'!C4:C153)=12)*(YEAR('Raw Data'!C4:C153)=2024))/E15,0) -> 0.4158 | G15: =D15-D14 -> -41800 | H15: =IF(G15>0,"▲ Growth","▼ Decline") -> ▼ Decline
B16: 13 | C16: Jan-25 | D16: =SUMPRODUCT(('Raw Data'!G4:G153)*(MONTH('Raw Data'!C4:C153)=1)*(YEAR('Raw Data'!C4:C153)=2025)) -> 408000 | E16: =SUMPRODUCT(('Raw Data'!B4:B153<>"")*(MONTH('Raw Data'!C4:C153)=1)*(YEAR('Raw Data'!C4:C153)=2025)) -> 10 | F16: =IFERROR(SUMPRODUCT(('Raw Data'!J4:J153)*(MONTH('Raw Data'!C4:C153)=1)*(YEAR('Raw Data'!C4:C153)=2025))/E16,0) -> 0.3829 | G16: =D16-D15 -> -120500 | H16: =IF(G16>0,"▲ Growth","▼ Decline") -> ▼ Decline
B17: 14 | C17: Feb-25 | D17: =SUMPRODUCT(('Raw Data'!G4:G153)*(MONTH('Raw Data'!C4:C153)=2)*(YEAR('Raw Data'!C4:C153)=2025)) -> 355400 | E17: =SUMPRODUCT(('Raw Data'!B4:B153<>"")*(MONTH('Raw Data'!C4:C153)=2)*(YEAR('Raw Data'!C4:C153)=2025)) -> 10 | F17: =IFERROR(SUMPRODUCT(('Raw Data'!J4:J153)*(MONTH('Raw Data'!C4:C153)=2)*(YEAR('Raw Data'!C4:C153)=2025))/E17,0) -> 0.4213 | G17: =D17-D16 -> -52600 | H17: =IF(G17>0,"▲ Growth","▼ Decline") -> ▼ Decline
B18: 15 | C18: Mar-25 | D18: =SUMPRODUCT(('Raw Data'!G4:G153)*(MONTH('Raw Data'!C4:C153)=3)*(YEAR('Raw Data'!C4:C153)=2025)) -> 244000 | E18: =SUMPRODUCT(('Raw Data'!B4:B153<>"")*(MONTH('Raw Data'!C4:C153)=3)*(YEAR('Raw Data'!C4:C153)=2025)) -> 8 | F18: =IFERROR(SUMPRODUCT(('Raw Data'!J4:J153)*(MONTH('Raw Data'!C4:C153)=3)*(YEAR('Raw Data'!C4:C153)=2025))/E18,0) -> 0.3995 | G18: =D18-D17 -> -111400 | H18: =IF(G18>0,"▲ Growth","▼ Decline") -> ▼ Decline
B19: 16 | C19: Apr-25 | D19: =SUMPRODUCT(('Raw Data'!G4:G153)*(MONTH('Raw Data'!C4:C153)=4)*(YEAR('Raw Data'!C4:C153)=2025)) -> 0 | E19: =SUMPRODUCT(('Raw Data'!B4:B153<>"")*(MONTH('Raw Data'!C4:C153)=4)*(YEAR('Raw Data'!C4:C153)=2025)) -> 0 | F19: =IFERROR(SUMPRODUCT(('Raw Data'!J4:J153)*(MONTH('Raw Data'!C4:C153)=4)*(YEAR('Raw Data'!C4:C153)=2025))/E19,0) -> 0 | G19: =D19-D18 -> -244000 | H19: =IF(G19>0,"▲ Growth","▼ Decline") -> ▼ Decline
B20: 17 | C20: May-25 | D20: =SUMPRODUCT(('Raw Data'!G4:G153)*(MONTH('Raw Data'!C4:C153)=5)*(YEAR('Raw Data'!C4:C153)=2025)) -> 0 | E20: =SUMPRODUCT(('Raw Data'!B4:B153<>"")*(MONTH('Raw Data'!C4:C153)=5)*(YEAR('Raw Data'!C4:C153)=2025)) -> 0 | F20: =IFERROR(SUMPRODUCT(('Raw Data'!J4:J153)*(MONTH('Raw Data'!C4:C153)=5)*(YEAR('Raw Data'!C4:C153)=2025))/E20,0) -> 0 | G20: =D20-D19 -> 0 | H20: =IF(G20>0,"▲ Growth","▼ Decline") -> ▼ Decline
B21: 18 | C21: Jun-25 | D21: =SUMPRODUCT(('Raw Data'!G4:G153)*(MONTH('Raw Data'!C4:C153)=6)*(YEAR('Raw Data'!C4:C153)=2025)) -> 0 | E21: =SUMPRODUCT(('Raw Data'!B4:B153<>"")*(MONTH('Raw Data'!C4:C153)=6)*(YEAR('Raw Data'!C4:C153)=2025)) -> 0 | F21: =IFERROR(SUMPRODUCT(('Raw Data'!J4:J153)*(MONTH('Raw Data'!C4:C153)=6)*(YEAR('Raw Data'!C4:C153)=2025))/E21,0) -> 0 | G21: =D21-D20 -> 0 | H21: =IF(G21>0,"▲ Growth","▼ Decline") -> ▼ Decline
B22: TOTAL | C22: 18 Months | D22: =SUM(D4:D21) -> 5671300 | E22: =SUM(E4:E21) -> 150 | F22: =AVERAGE(F4:F21) -> 0.33680713
B24: HOW TO BUILD YOUR TREND CHART FROM THIS TABLE
B25: Step 1: Select C3:C21 + D3:D21 (Period labels + Revenue). Hold Ctrl to select both columns.
B26: Step 2: Insert → Charts → Line → Line with Markers. Title: 'Monthly Revenue Trend (Jan 2024 – Jun 2025)'
B27: Step 3: Right-click chart → Move Chart → place it in the Dashboard (Your Work) sheet, Section 5 right zone.
B28: Step 4: Add data labels on the line. Format → Data Labels → Above. Remove gridlines. Remove legend (single series).
B29: Step 5: Format the line in dark blue (#1F3864). Marker size = 6. This is your client-ready trend chart.

Sheet Concept Notes
B1: DAY 16 CONCEPT NOTES | What Makes a Real Client Dashboard
B3: THE 6-PART DASHBOARD FRAMEWORK
B4: Part | C4: What it contains | D4: Why it matters in real client work
B5: 1. Raw Data | C5: Unmodified flat table — all rows, all columns, no totals | D5: The source of truth. If you modify raw data, your analysis can't be audited or reproduced.
B6: 2. KPI Cards | C6: 4–6 headline numbers at the top — total revenue, orders, avg margin | D6: Clients see these first. They should answer 'How are we doing?' in 5 seconds.
B7: 3. Region / Category Summary | C7: SUMIF tables showing revenue, orders, margin per group | D7: Shows WHERE the money comes from — concentration risk or growth opportunity.
B8: 4. Leaderboard | C8: Rep performance table — who is carrying the team, who needs coaching | D8: People data = action data. Every client wants to know who their top performer is.
B9: 5. Charts | C9: Bar (comparison) + Line (trend) — the two most used chart types | D9: Visual = faster insight. Time series belongs on a Line. Category comparison belongs on a Bar.
B10: 6. Executive Summary | C10: 5 written insights using Number + Reason + Action format | D10: This is what separates a data analyst from a data entry person. Anyone can build a table. Few can explain what it means.
B13: COMMON MISTAKES IN WEEK 4 DASHBOARDS
B14: Mistake | C14: Why it fails | D14: Fix
B15: Hardcoding values in KPI cards | C15: The number is frozen — updating raw data doesn't update the card | D15: Always use formulas: =SUMIF(), =COUNTA(), =AVERAGE()
B16: Charts on separate chart sheets | C16: Client opens file, sees a table, misses the chart entirely | D16: Always move charts to the Dashboard sheet using 'Move Chart'
B17: Insights that are just observations | C17: 'South has highest revenue' tells the client what they can already see | D17: Add the action: 'South leads by ₹X — replicate its top-rep strategy in Central'
B18: Using % of Total wrong | C18: SUMIF(range, criterion, sum_range) — pulls only rows matching the criterion | D18: The dashboard recalculates automatically — no manual re-entry when data refreshes
B19: Performance tag without IFS logic | C19: Manually typing 'High' / 'Low' breaks when data refreshes | D19: Use IFS() to auto-tag based on AVERAGE() or LARGE() thresholds
B20: Pivot table not refreshed | C20: Pivot shows last session's data even after raw data was updated | D20: Right-click pivot → Refresh, OR Data tab → Refresh All before presenting
B23: THE NUMBER + REASON + ACTION FORMAT
B24: Component | C24: What it is | D24: Example (Electronics category)
B25: Number | C25: The specific data point — not a vague reference | D25: Electronics = ₹42,00,000 (38.2% of total revenue)
B26: Reason | C26: Why this number matters — risk, opportunity, or pattern | D26: 38% concentration in one category creates fragility — a supply disruption would be catastrophic
B27: Action | C27: What the business should do — specific, time-bound if possible | D27: Grow Fitness and Footwear to 15% share each within 6 months to reduce Electronics dependency
B28: Combined | C28: One sentence that clients can act on | D28: 'Electronics drives 38% of revenue — diversify into Fitness and Footwear to 15% each within H2 to reduce concentration risk.'
B31: INTERVIEW FRAMING — DAY 16
B32: Question | C32: Weak answer | D32: Strong answer (use this)
B33: 'Walk me through how you built this dashboard' | C33: 'I used SUMIF and made some charts' | D33: 'I started with a flat raw data table, then built SUMIF summaries by region and category, IFS-based performance tags, two charts for comparison and trend, and a written executive summary. The whole thing is formula-driven — change any row in raw data and every number updates instantly.'
B34: 'Why did you use IFS instead of IF for the performance grade?' | C34: 'IFS is easier to write' | D34: 'IFS handles multiple conditions cleanly in one formula without nesting. For three grades — High, Target, Coaching — nested IFs become hard to read and debug. IFS reads like a decision table, which is better for a file someone else will maintain.'
B35: 'How would you make this dashboard interactive for a client?' | C35: 'I would add slicers' | D35: 'Convert the raw data to an Excel Table (Ctrl+T), build pivot tables on top of it, add Region and Category slicers connected to all pivots, and a pivot chart that auto-updates on slicer clicks. That removes the need for the client to understand formulas — they just click.'

Sheet Scoring Guide
B1: DAY 16 SCORING GUIDE | Week 4 Mini-Project | Total: 80 Points
B2: This is your highest-stakes submission yet — 80 points, 6 sections, capstone of Month 1
B3: Task / Section | C3: Skill Tested | D3: Success Criteria | E3: Pts
B4: KPI Cards (5 cards) | C4: SUMIF / COUNTA / AVERAGE | D4: All 5 KPI cards use formulas referencing Raw Data. No hardcoded values. Correct calculations. Number formats applied. | E4: 10
B5: Region Summary Table | C5: SUMIF / COUNTIF / AVERAGEIF / IFS | D5: All 5 regions present. Revenue, %, Orders, Avg Order Value, Avg Margin all formula-driven. IFS Performance Tag auto-generates correctly. Grand Total row. | E5: 15
B6: Category Summary Table | C6: SUMIF / COUNTIF / AVERAGEIF | D6: All 6 categories present. Revenue + % + Orders + Avg Margin correct. Data Bar CF applied to Revenue Bar column. Grand Total. | E6: 12
B7: Rep Leaderboard | C7: SUMIF / COUNTIF / IFS | D7: All 10 reps present. Revenue and Order counts correct via SUMIF/COUNTIF on Sales Rep column. IFS grade tag works. Sorted by revenue descending (bonus if done). | E7: 13
B8: 2 Charts (Region Bar + Trend Line) | C8: Chart creation | D8: Chart 1: Clustered Bar — Revenue by Region. Title, data labels, no 3D, no gridlines. Chart 2: Line — Monthly Revenue Trend from Monthly Summary table. Markers, title, no gridlines. Both on Dashboard sheet. | E8: 15
B9: Executive Summary (5 Insights) | C9: Communication | D9: All 5 insights answered. Each uses Number + Reason + Action format. No insight is a pure observation — all 5 must include an action/recommendation. Specific ₹ figures cited. | E9: 15
B10: BONUS: Conditional Formatting | C10: CF | D10: Data Bar on Category Revenue Bar column. Colour scale or icon set on Rep Leaderboard revenue column. Both applied from formula columns, not raw data. | E10: +5 Bonus
B11: BONUS: Raw Data rule | C11: Discipline | D11: Raw Data sheet untouched — no added columns, no deleted rows, no modifications whatsoever. | E11: +3 Bonus
B12: TOTAL (excl. bonus) | E12: 80
B14: GRADING BANDS
B15: 74–80+ | C15: Distinction | D15: Month 1 complete. You have a real client dashboard in your portfolio. GitHub-ready.
B16: 62–73 | C16: Pass | D16: Strong technical work. Written insights need one more revision pass.
B17: 48–61 | C17: Needs Work | D17: Charts or formulas incomplete. Resubmit before moving to Month 2.
B18: 0–47 | C18: Re-attempt | D18: Rebuild sections 2–4 first. Post questions before resubmitting.
B20: KEY TAKEAWAYS — DAY 16 (Month 1 Capstone)
B21: 1. A dashboard is not a collection of tables — it is a decision-support tool. Every element must answer a question a manager actually has.
B22: 2. IFS() for performance tags is not a formula trick — it's a business rule encoded in a cell. Change the threshold, change the company's definition of 'high performer'.
B23: 3. The Executive Summary is the hardest part to write but the most valuable. Anyone can build the table. The insight is what you're being paid for.
B24: 4. Raw data is untouched. Always. In real client work, you will be blamed if the source data is modified — even if you improved it.
B25: 5. Formula-driven dashboards vs. static dashboards: one takes 5 minutes to update when data changes. The other takes 2 hours. Always build formula-driven.
B26: INTERVIEW: 'What's the hardest part of building a dashboard for a client?' → 'Not the technical part — the technical part is repeatable. The hardest part is writing the insights: translating numbers into decisions the client can act on the same day.'
